[2020-08-30 16:23:12 +0800] [15203] [ERROR] Error handling request /score/grade
Traceback (most recent call last):
  File "/data/wwwroot/default/gong/jwxt/virtualenv/lib/python3.6/site-packages/pymysql/connections.py", line 683, in _read_bytes
    data = self._rfile.read(num_bytes)
  File "/usr/lib64/python3.6/socket.py", line 586, in readinto
    return self._sock.recv_into(b)
  File "/data/wwwroot/default/gong/jwxt/virtualenv/lib64/python3.6/site-packages/gevent/_socket3.py", line 505, in recv_into
    return self._sock.recv_into(*args)
ConnectionResetError: [Errno 104] Connection reset by peer

During handling of the above exception, another exception occurred:

Traceback (most recent call last):
  File "/data/wwwroot/default/gong/jwxt/virtualenv/lib/python3.6/site-packages/gunicorn/workers/base_async.py", line 55, in handle
    self.handle_request(listener_name, req, client, addr)
  File "/data/wwwroot/default/gong/jwxt/virtualenv/lib/python3.6/site-packages/gunicorn/workers/ggevent.py", line 143, in handle_request
    super().handle_request(listener_name, req, sock, addr)
  File "/data/wwwroot/default/gong/jwxt/virtualenv/lib/python3.6/site-packages/gunicorn/workers/base_async.py", line 106, in handle_request
    respiter = self.wsgi(environ, resp.start_response)
  File "/data/wwwroot/default/gong/jwxt/virtualenv/lib/python3.6/site-packages/flask/app.py", line 2464, in __call__
    return self.wsgi_app(environ, start_response)
  File "/data/wwwroot/default/gong/jwxt/virtualenv/lib/python3.6/site-packages/flask/app.py", line 2450, in wsgi_app
    response = self.handle_exception(e)
  File "/data/wwwroot/default/gong/jwxt/virtualenv/lib/python3.6/site-packages/flask/app.py", line 1867, in handle_exception
    reraise(exc_type, exc_value, tb)
  File "/data/wwwroot/default/gong/jwxt/virtualenv/lib/python3.6/site-packages/flask/_compat.py", line 39, in reraise
    raise value
  File "/data/wwwroot/default/gong/jwxt/virtualenv/lib/python3.6/site-packages/flask/app.py", line 2447, in wsgi_app
    response = self.full_dispatch_request()
  File "/data/wwwroot/default/gong/jwxt/virtualenv/lib/python3.6/site-packages/flask/app.py", line 1952, in full_dispatch_request
    rv = self.handle_user_exception(e)
  File "/data/wwwroot/default/gong/jwxt/virtualenv/lib/python3.6/site-packages/flask/app.py", line 1821, in handle_user_exception
    reraise(exc_type, exc_value, tb)
  File "/data/wwwroot/default/gong/jwxt/virtualenv/lib/python3.6/site-packages/flask/_compat.py", line 39, in reraise
    raise value
  File "/data/wwwroot/default/gong/jwxt/virtualenv/lib/python3.6/site-packages/flask/app.py", line 1950, in full_dispatch_request
    rv = self.dispatch_request()
  File "/data/wwwroot/default/gong/jwxt/virtualenv/lib/python3.6/site-packages/flask/app.py", line 1936, in dispatch_request
    return self.view_functions[rule.endpoint](**req.view_args)
  File "/data/wwwroot/default/gong/jwxt/app.py", line 78, in get_grade
    flag = pipiline.get_flag()
  File "/data/wwwroot/default/gong/jwxt/pipeline.py", line 49, in get_flag
    self.cursor.execute(self.check_flag_sql)
  File "/data/wwwroot/default/gong/jwxt/virtualenv/lib/python3.6/site-packages/pymysql/cursors.py", line 163, in execute
    result = self._query(query)
  File "/data/wwwroot/default/gong/jwxt/virtualenv/lib/python3.6/site-packages/pymysql/cursors.py", line 321, in _query
    conn.query(q)
  File "/data/wwwroot/default/gong/jwxt/virtualenv/lib/python3.6/site-packages/pymysql/connections.py", line 505, in query
    self._affected_rows = self._read_query_result(unbuffered=unbuffered)
  File "/data/wwwroot/default/gong/jwxt/virtualenv/lib/python3.6/site-packages/pymysql/connections.py", line 724, in _read_query_result
    result.read()
  File "/data/wwwroot/default/gong/jwxt/virtualenv/lib/python3.6/site-packages/pymysql/connections.py", line 1069, in read
    first_packet = self.connection._read_packet()
  File "/data/wwwroot/default/gong/jwxt/virtualenv/lib/python3.6/site-packages/pymysql/connections.py", line 646, in _read_packet
    packet_header = self._read_bytes(4)
  File "/data/wwwroot/default/gong/jwxt/virtualenv/lib/python3.6/site-packages/pymysql/connections.py", line 691, in _read_bytes
    "Lost connection to MySQL server during query (%s)" % (e,))
pymysql.err.OperationalError: (2013, 'Lost connection to MySQL server during query ([Errno 104] Connection reset by peer)')
[2020-08-30 16:24:13 +0800] [28860] [ERROR] Error handling request /score/grade
Traceback (most recent call last):
  File "/data/wwwroot/default/gong/jwxt/virtualenv/lib/python3.6/site-packages/gunicorn/workers/base_async.py", line 55, in handle
    self.handle_request(listener_name, req, client, addr)
  File "/data/wwwroot/default/gong/jwxt/virtualenv/lib/python3.6/site-packages/gunicorn/workers/ggevent.py", line 143, in handle_request
    super().handle_request(listener_name, req, sock, addr)
  File "/data/wwwroot/default/gong/jwxt/virtualenv/lib/python3.6/site-packages/gunicorn/workers/base_async.py", line 106, in handle_request
    respiter = self.wsgi(environ, resp.start_response)
  File "/data/wwwroot/default/gong/jwxt/virtualenv/lib/python3.6/site-packages/flask/app.py", line 2464, in __call__
    return self.wsgi_app(environ, start_response)
  File "/data/wwwroot/default/gong/jwxt/virtualenv/lib/python3.6/site-packages/flask/app.py", line 2450, in wsgi_app
    response = self.handle_exception(e)
  File "/data/wwwroot/default/gong/jwxt/virtualenv/lib/python3.6/site-packages/flask/app.py", line 1867, in handle_exception
    reraise(exc_type, exc_value, tb)
  File "/data/wwwroot/default/gong/jwxt/virtualenv/lib/python3.6/site-packages/flask/_compat.py", line 39, in reraise
    raise value
  File "/data/wwwroot/default/gong/jwxt/virtualenv/lib/python3.6/site-packages/flask/app.py", line 2447, in wsgi_app
    response = self.full_dispatch_request()
  File "/data/wwwroot/default/gong/jwxt/virtualenv/lib/python3.6/site-packages/flask/app.py", line 1952, in full_dispatch_request
    rv = self.handle_user_exception(e)
  File "/data/wwwroot/default/gong/jwxt/virtualenv/lib/python3.6/site-packages/flask/app.py", line 1821, in handle_user_exception
    reraise(exc_type, exc_value, tb)
  File "/data/wwwroot/default/gong/jwxt/virtualenv/lib/python3.6/site-packages/flask/_compat.py", line 39, in reraise
    raise value
  File "/data/wwwroot/default/gong/jwxt/virtualenv/lib/python3.6/site-packages/flask/app.py", line 1950, in full_dispatch_request
    rv = self.dispatch_request()
  File "/data/wwwroot/default/gong/jwxt/virtualenv/lib/python3.6/site-packages/flask/app.py", line 1936, in dispatch_request
    return self.view_functions[rule.endpoint](**req.view_args)
  File "/data/wwwroot/default/gong/jwxt/app.py", line 78, in get_grade
    flag = pipiline.get_flag()
  File "/data/wwwroot/default/gong/jwxt/pipeline.py", line 53, in get_flag
    self.cursor.execute(self.insert_update_time_sql)
  File "/data/wwwroot/default/gong/jwxt/virtualenv/lib/python3.6/site-packages/pymysql/cursors.py", line 163, in execute
    result = self._query(query)
  File "/data/wwwroot/default/gong/jwxt/virtualenv/lib/python3.6/site-packages/pymysql/cursors.py", line 321, in _query
    conn.query(q)
  File "/data/wwwroot/default/gong/jwxt/virtualenv/lib/python3.6/site-packages/pymysql/connections.py", line 505, in query
    self._affected_rows = self._read_query_result(unbuffered=unbuffered)
  File "/data/wwwroot/default/gong/jwxt/virtualenv/lib/python3.6/site-packages/pymysql/connections.py", line 724, in _read_query_result
    result.read()
  File "/data/wwwroot/default/gong/jwxt/virtualenv/lib/python3.6/site-packages/pymysql/connections.py", line 1069, in read
    first_packet = self.connection._read_packet()
  File "/data/wwwroot/default/gong/jwxt/virtualenv/lib/python3.6/site-packages/pymysql/connections.py", line 676, in _read_packet
    packet.raise_for_error()
  File "/data/wwwroot/default/gong/jwxt/virtualenv/lib/python3.6/site-packages/pymysql/protocol.py", line 223, in raise_for_error
    err.raise_mysql_exception(self._data)
  File "/data/wwwroot/default/gong/jwxt/virtualenv/lib/python3.6/site-packages/pymysql/err.py", line 107, in raise_mysql_exception
    raise errorclass(errno, errval)
pymysql.err.OperationalError: (1054, "Unknown column 'grade' in 'field list'")
[2020-08-30 16:27:36 +0800] [28860] [ERROR] Error handling request /score/grade
Traceback (most recent call last):
  File "/data/wwwroot/default/gong/jwxt/virtualenv/lib/python3.6/site-packages/gunicorn/workers/base_async.py", line 55, in handle
    self.handle_request(listener_name, req, client, addr)
  File "/data/wwwroot/default/gong/jwxt/virtualenv/lib/python3.6/site-packages/gunicorn/workers/ggevent.py", line 143, in handle_request
    super().handle_request(listener_name, req, sock, addr)
  File "/data/wwwroot/default/gong/jwxt/virtualenv/lib/python3.6/site-packages/gunicorn/workers/base_async.py", line 106, in handle_request
    respiter = self.wsgi(environ, resp.start_response)
  File "/data/wwwroot/default/gong/jwxt/virtualenv/lib/python3.6/site-packages/flask/app.py", line 2464, in __call__
    return self.wsgi_app(environ, start_response)
  File "/data/wwwroot/default/gong/jwxt/virtualenv/lib/python3.6/site-packages/flask/app.py", line 2450, in wsgi_app
    response = self.handle_exception(e)
  File "/data/wwwroot/default/gong/jwxt/virtualenv/lib/python3.6/site-packages/flask/app.py", line 1867, in handle_exception
    reraise(exc_type, exc_value, tb)
  File "/data/wwwroot/default/gong/jwxt/virtualenv/lib/python3.6/site-packages/flask/_compat.py", line 39, in reraise
    raise value
  File "/data/wwwroot/default/gong/jwxt/virtualenv/lib/python3.6/site-packages/flask/app.py", line 2447, in wsgi_app
    response = self.full_dispatch_request()
  File "/data/wwwroot/default/gong/jwxt/virtualenv/lib/python3.6/site-packages/flask/app.py", line 1952, in full_dispatch_request
    rv = self.handle_user_exception(e)
  File "/data/wwwroot/default/gong/jwxt/virtualenv/lib/python3.6/site-packages/flask/app.py", line 1821, in handle_user_exception
    reraise(exc_type, exc_value, tb)
  File "/data/wwwroot/default/gong/jwxt/virtualenv/lib/python3.6/site-packages/flask/_compat.py", line 39, in reraise
    raise value
  File "/data/wwwroot/default/gong/jwxt/virtualenv/lib/python3.6/site-packages/flask/app.py", line 1950, in full_dispatch_request
    rv = self.dispatch_request()
  File "/data/wwwroot/default/gong/jwxt/virtualenv/lib/python3.6/site-packages/flask/app.py", line 1936, in dispatch_request
    return self.view_functions[rule.endpoint](**req.view_args)
  File "/data/wwwroot/default/gong/jwxt/app.py", line 78, in get_grade
    flag = pipiline.get_flag()
  File "/data/wwwroot/default/gong/jwxt/pipeline.py", line 49, in get_flag
    self.cursor.execute(self.check_flag_sql)
  File "/data/wwwroot/default/gong/jwxt/virtualenv/lib/python3.6/site-packages/pymysql/cursors.py", line 163, in execute
    result = self._query(query)
  File "/data/wwwroot/default/gong/jwxt/virtualenv/lib/python3.6/site-packages/pymysql/cursors.py", line 321, in _query
    conn.query(q)
  File "/data/wwwroot/default/gong/jwxt/virtualenv/lib/python3.6/site-packages/pymysql/connections.py", line 505, in query
    self._affected_rows = self._read_query_result(unbuffered=unbuffered)
  File "/data/wwwroot/default/gong/jwxt/virtualenv/lib/python3.6/site-packages/pymysql/connections.py", line 724, in _read_query_result
    result.read()
  File "/data/wwwroot/default/gong/jwxt/virtualenv/lib/python3.6/site-packages/pymysql/connections.py", line 1069, in read
    first_packet = self.connection._read_packet()
  File "/data/wwwroot/default/gong/jwxt/virtualenv/lib/python3.6/site-packages/pymysql/connections.py", line 646, in _read_packet
    packet_header = self._read_bytes(4)
  File "/data/wwwroot/default/gong/jwxt/virtualenv/lib/python3.6/site-packages/pymysql/connections.py", line 699, in _read_bytes
    CR.CR_SERVER_LOST, "Lost connection to MySQL server during query")
pymysql.err.OperationalError: (2013, 'Lost connection to MySQL server during query')
[2020-08-30 16:28:42 +0800] [28860] [ERROR] Error handling request /score/grade
Traceback (most recent call last):
  File "/data/wwwroot/default/gong/jwxt/virtualenv/lib/python3.6/site-packages/gunicorn/workers/base_async.py", line 55, in handle
    self.handle_request(listener_name, req, client, addr)
  File "/data/wwwroot/default/gong/jwxt/virtualenv/lib/python3.6/site-packages/gunicorn/workers/ggevent.py", line 143, in handle_request
    super().handle_request(listener_name, req, sock, addr)
  File "/data/wwwroot/default/gong/jwxt/virtualenv/lib/python3.6/site-packages/gunicorn/workers/base_async.py", line 106, in handle_request
    respiter = self.wsgi(environ, resp.start_response)
  File "/data/wwwroot/default/gong/jwxt/virtualenv/lib/python3.6/site-packages/flask/app.py", line 2464, in __call__
    return self.wsgi_app(environ, start_response)
  File "/data/wwwroot/default/gong/jwxt/virtualenv/lib/python3.6/site-packages/flask/app.py", line 2450, in wsgi_app
    response = self.handle_exception(e)
  File "/data/wwwroot/default/gong/jwxt/virtualenv/lib/python3.6/site-packages/flask/app.py", line 1867, in handle_exception
    reraise(exc_type, exc_value, tb)
  File "/data/wwwroot/default/gong/jwxt/virtualenv/lib/python3.6/site-packages/flask/_compat.py", line 39, in reraise
    raise value
  File "/data/wwwroot/default/gong/jwxt/virtualenv/lib/python3.6/site-packages/flask/app.py", line 2447, in wsgi_app
    response = self.full_dispatch_request()
  File "/data/wwwroot/default/gong/jwxt/virtualenv/lib/python3.6/site-packages/flask/app.py", line 1952, in full_dispatch_request
    rv = self.handle_user_exception(e)
  File "/data/wwwroot/default/gong/jwxt/virtualenv/lib/python3.6/site-packages/flask/app.py", line 1821, in handle_user_exception
    reraise(exc_type, exc_value, tb)
  File "/data/wwwroot/default/gong/jwxt/virtualenv/lib/python3.6/site-packages/flask/_compat.py", line 39, in reraise
    raise value
  File "/data/wwwroot/default/gong/jwxt/virtualenv/lib/python3.6/site-packages/flask/app.py", line 1950, in full_dispatch_request
    rv = self.dispatch_request()
  File "/data/wwwroot/default/gong/jwxt/virtualenv/lib/python3.6/site-packages/flask/app.py", line 1936, in dispatch_request
    return self.view_functions[rule.endpoint](**req.view_args)
  File "/data/wwwroot/default/gong/jwxt/app.py", line 78, in get_grade
    flag = pipiline.get_flag()
  File "/data/wwwroot/default/gong/jwxt/pipeline.py", line 49, in get_flag
    self.cursor.execute(self.check_flag_sql)
  File "/data/wwwroot/default/gong/jwxt/virtualenv/lib/python3.6/site-packages/pymysql/cursors.py", line 163, in execute
    result = self._query(query)
  File "/data/wwwroot/default/gong/jwxt/virtualenv/lib/python3.6/site-packages/pymysql/cursors.py", line 321, in _query
    conn.query(q)
  File "/data/wwwroot/default/gong/jwxt/virtualenv/lib/python3.6/site-packages/pymysql/connections.py", line 504, in query
    self._execute_command(COMMAND.COM_QUERY, sql)
  File "/data/wwwroot/default/gong/jwxt/virtualenv/lib/python3.6/site-packages/pymysql/connections.py", line 742, in _execute_command
    raise err.InterfaceError(0, '')
pymysql.err.InterfaceError: (0, '')
[2020-08-30 16:28:54 +0800] [28860] [ERROR] Error handling request /score/grade
Traceback (most recent call last):
  File "/data/wwwroot/default/gong/jwxt/virtualenv/lib/python3.6/site-packages/gunicorn/workers/base_async.py", line 55, in handle
    self.handle_request(listener_name, req, client, addr)
  File "/data/wwwroot/default/gong/jwxt/virtualenv/lib/python3.6/site-packages/gunicorn/workers/ggevent.py", line 143, in handle_request
    super().handle_request(listener_name, req, sock, addr)
  File "/data/wwwroot/default/gong/jwxt/virtualenv/lib/python3.6/site-packages/gunicorn/workers/base_async.py", line 106, in handle_request
    respiter = self.wsgi(environ, resp.start_response)
  File "/data/wwwroot/default/gong/jwxt/virtualenv/lib/python3.6/site-packages/flask/app.py", line 2464, in __call__
    return self.wsgi_app(environ, start_response)
  File "/data/wwwroot/default/gong/jwxt/virtualenv/lib/python3.6/site-packages/flask/app.py", line 2450, in wsgi_app
    response = self.handle_exception(e)
  File "/data/wwwroot/default/gong/jwxt/virtualenv/lib/python3.6/site-packages/flask/app.py", line 1867, in handle_exception
    reraise(exc_type, exc_value, tb)
  File "/data/wwwroot/default/gong/jwxt/virtualenv/lib/python3.6/site-packages/flask/_compat.py", line 39, in reraise
    raise value
  File "/data/wwwroot/default/gong/jwxt/virtualenv/lib/python3.6/site-packages/flask/app.py", line 2447, in wsgi_app
    response = self.full_dispatch_request()
  File "/data/wwwroot/default/gong/jwxt/virtualenv/lib/python3.6/site-packages/flask/app.py", line 1952, in full_dispatch_request
    rv = self.handle_user_exception(e)
  File "/data/wwwroot/default/gong/jwxt/virtualenv/lib/python3.6/site-packages/flask/app.py", line 1821, in handle_user_exception
    reraise(exc_type, exc_value, tb)
  File "/data/wwwroot/default/gong/jwxt/virtualenv/lib/python3.6/site-packages/flask/_compat.py", line 39, in reraise
    raise value
  File "/data/wwwroot/default/gong/jwxt/virtualenv/lib/python3.6/site-packages/flask/app.py", line 1950, in full_dispatch_request
    rv = self.dispatch_request()
  File "/data/wwwroot/default/gong/jwxt/virtualenv/lib/python3.6/site-packages/flask/app.py", line 1936, in dispatch_request
    return self.view_functions[rule.endpoint](**req.view_args)
  File "/data/wwwroot/default/gong/jwxt/app.py", line 78, in get_grade
    flag = pipiline.get_flag()
  File "/data/wwwroot/default/gong/jwxt/pipeline.py", line 49, in get_flag
    self.cursor.execute(self.check_flag_sql)
  File "/data/wwwroot/default/gong/jwxt/virtualenv/lib/python3.6/site-packages/pymysql/cursors.py", line 163, in execute
    result = self._query(query)
  File "/data/wwwroot/default/gong/jwxt/virtualenv/lib/python3.6/site-packages/pymysql/cursors.py", line 321, in _query
    conn.query(q)
  File "/data/wwwroot/default/gong/jwxt/virtualenv/lib/python3.6/site-packages/pymysql/connections.py", line 504, in query
    self._execute_command(COMMAND.COM_QUERY, sql)
  File "/data/wwwroot/default/gong/jwxt/virtualenv/lib/python3.6/site-packages/pymysql/connections.py", line 742, in _execute_command
    raise err.InterfaceError(0, '')
pymysql.err.InterfaceError: (0, '')
[2020-08-30 16:29:26 +0800] [28860] [ERROR] Error handling request /info
Traceback (most recent call last):
  File "/data/wwwroot/default/gong/jwxt/virtualenv/lib/python3.6/site-packages/gunicorn/workers/base_async.py", line 55, in handle
    self.handle_request(listener_name, req, client, addr)
  File "/data/wwwroot/default/gong/jwxt/virtualenv/lib/python3.6/site-packages/gunicorn/workers/ggevent.py", line 143, in handle_request
    super().handle_request(listener_name, req, sock, addr)
  File "/data/wwwroot/default/gong/jwxt/virtualenv/lib/python3.6/site-packages/gunicorn/workers/base_async.py", line 106, in handle_request
    respiter = self.wsgi(environ, resp.start_response)
  File "/data/wwwroot/default/gong/jwxt/virtualenv/lib/python3.6/site-packages/flask/app.py", line 2464, in __call__
    return self.wsgi_app(environ, start_response)
  File "/data/wwwroot/default/gong/jwxt/virtualenv/lib/python3.6/site-packages/flask/app.py", line 2450, in wsgi_app
    response = self.handle_exception(e)
  File "/data/wwwroot/default/gong/jwxt/virtualenv/lib/python3.6/site-packages/flask/app.py", line 1867, in handle_exception
    reraise(exc_type, exc_value, tb)
  File "/data/wwwroot/default/gong/jwxt/virtualenv/lib/python3.6/site-packages/flask/_compat.py", line 39, in reraise
    raise value
  File "/data/wwwroot/default/gong/jwxt/virtualenv/lib/python3.6/site-packages/flask/app.py", line 2447, in wsgi_app
    response = self.full_dispatch_request()
  File "/data/wwwroot/default/gong/jwxt/virtualenv/lib/python3.6/site-packages/flask/app.py", line 1952, in full_dispatch_request
    rv = self.handle_user_exception(e)
  File "/data/wwwroot/default/gong/jwxt/virtualenv/lib/python3.6/site-packages/flask/app.py", line 1821, in handle_user_exception
    reraise(exc_type, exc_value, tb)
  File "/data/wwwroot/default/gong/jwxt/virtualenv/lib/python3.6/site-packages/flask/_compat.py", line 39, in reraise
    raise value
  File "/data/wwwroot/default/gong/jwxt/virtualenv/lib/python3.6/site-packages/flask/app.py", line 1950, in full_dispatch_request
    rv = self.dispatch_request()
  File "/data/wwwroot/default/gong/jwxt/virtualenv/lib/python3.6/site-packages/flask/app.py", line 1936, in dispatch_request
    return self.view_functions[rule.endpoint](**req.view_args)
  File "/data/wwwroot/default/gong/jwxt/app.py", line 35, in get_info
    flag = pipiline.get_flag()
  File "/data/wwwroot/default/gong/jwxt/pipeline.py", line 49, in get_flag
    self.cursor.execute(self.check_flag_sql)
  File "/data/wwwroot/default/gong/jwxt/virtualenv/lib/python3.6/site-packages/pymysql/cursors.py", line 163, in execute
    result = self._query(query)
  File "/data/wwwroot/default/gong/jwxt/virtualenv/lib/python3.6/site-packages/pymysql/cursors.py", line 321, in _query
    conn.query(q)
  File "/data/wwwroot/default/gong/jwxt/virtualenv/lib/python3.6/site-packages/pymysql/connections.py", line 504, in query
    self._execute_command(COMMAND.COM_QUERY, sql)
  File "/data/wwwroot/default/gong/jwxt/virtualenv/lib/python3.6/site-packages/pymysql/connections.py", line 742, in _execute_command
    raise err.InterfaceError(0, '')
pymysql.err.InterfaceError: (0, '')
[2020-08-30 16:31:34 +0800] [28860] [ERROR] Error handling request /info
Traceback (most recent call last):
  File "/data/wwwroot/default/gong/jwxt/virtualenv/lib/python3.6/site-packages/gunicorn/workers/base_async.py", line 55, in handle
    self.handle_request(listener_name, req, client, addr)
  File "/data/wwwroot/default/gong/jwxt/virtualenv/lib/python3.6/site-packages/gunicorn/workers/ggevent.py", line 143, in handle_request
    super().handle_request(listener_name, req, sock, addr)
  File "/data/wwwroot/default/gong/jwxt/virtualenv/lib/python3.6/site-packages/gunicorn/workers/base_async.py", line 106, in handle_request
    respiter = self.wsgi(environ, resp.start_response)
  File "/data/wwwroot/default/gong/jwxt/virtualenv/lib/python3.6/site-packages/flask/app.py", line 2464, in __call__
    return self.wsgi_app(environ, start_response)
  File "/data/wwwroot/default/gong/jwxt/virtualenv/lib/python3.6/site-packages/flask/app.py", line 2450, in wsgi_app
    response = self.handle_exception(e)
  File "/data/wwwroot/default/gong/jwxt/virtualenv/lib/python3.6/site-packages/flask/app.py", line 1867, in handle_exception
    reraise(exc_type, exc_value, tb)
  File "/data/wwwroot/default/gong/jwxt/virtualenv/lib/python3.6/site-packages/flask/_compat.py", line 39, in reraise
    raise value
  File "/data/wwwroot/default/gong/jwxt/virtualenv/lib/python3.6/site-packages/flask/app.py", line 2447, in wsgi_app
    response = self.full_dispatch_request()
  File "/data/wwwroot/default/gong/jwxt/virtualenv/lib/python3.6/site-packages/flask/app.py", line 1952, in full_dispatch_request
    rv = self.handle_user_exception(e)
  File "/data/wwwroot/default/gong/jwxt/virtualenv/lib/python3.6/site-packages/flask/app.py", line 1821, in handle_user_exception
    reraise(exc_type, exc_value, tb)
  File "/data/wwwroot/default/gong/jwxt/virtualenv/lib/python3.6/site-packages/flask/_compat.py", line 39, in reraise
    raise value
  File "/data/wwwroot/default/gong/jwxt/virtualenv/lib/python3.6/site-packages/flask/app.py", line 1950, in full_dispatch_request
    rv = self.dispatch_request()
  File "/data/wwwroot/default/gong/jwxt/virtualenv/lib/python3.6/site-packages/flask/app.py", line 1936, in dispatch_request
    return self.view_functions[rule.endpoint](**req.view_args)
  File "/data/wwwroot/default/gong/jwxt/app.py", line 35, in get_info
    flag = pipiline.get_flag()
  File "/data/wwwroot/default/gong/jwxt/pipeline.py", line 49, in get_flag
    self.cursor.execute(self.check_flag_sql)
  File "/data/wwwroot/default/gong/jwxt/virtualenv/lib/python3.6/site-packages/pymysql/cursors.py", line 163, in execute
    result = self._query(query)
  File "/data/wwwroot/default/gong/jwxt/virtualenv/lib/python3.6/site-packages/pymysql/cursors.py", line 321, in _query
    conn.query(q)
  File "/data/wwwroot/default/gong/jwxt/virtualenv/lib/python3.6/site-packages/pymysql/connections.py", line 504, in query
    self._execute_command(COMMAND.COM_QUERY, sql)
  File "/data/wwwroot/default/gong/jwxt/virtualenv/lib/python3.6/site-packages/pymysql/connections.py", line 742, in _execute_command
    raise err.InterfaceError(0, '')
pymysql.err.InterfaceError: (0, '')
[2020-08-30 16:31:52 +0800] [28860] [ERROR] Error handling request /course
Traceback (most recent call last):
  File "/data/wwwroot/default/gong/jwxt/virtualenv/lib/python3.6/site-packages/gunicorn/workers/base_async.py", line 55, in handle
    self.handle_request(listener_name, req, client, addr)
  File "/data/wwwroot/default/gong/jwxt/virtualenv/lib/python3.6/site-packages/gunicorn/workers/ggevent.py", line 143, in handle_request
    super().handle_request(listener_name, req, sock, addr)
  File "/data/wwwroot/default/gong/jwxt/virtualenv/lib/python3.6/site-packages/gunicorn/workers/base_async.py", line 106, in handle_request
    respiter = self.wsgi(environ, resp.start_response)
  File "/data/wwwroot/default/gong/jwxt/virtualenv/lib/python3.6/site-packages/flask/app.py", line 2464, in __call__
    return self.wsgi_app(environ, start_response)
  File "/data/wwwroot/default/gong/jwxt/virtualenv/lib/python3.6/site-packages/flask/app.py", line 2450, in wsgi_app
    response = self.handle_exception(e)
  File "/data/wwwroot/default/gong/jwxt/virtualenv/lib/python3.6/site-packages/flask/app.py", line 1867, in handle_exception
    reraise(exc_type, exc_value, tb)
  File "/data/wwwroot/default/gong/jwxt/virtualenv/lib/python3.6/site-packages/flask/_compat.py", line 39, in reraise
    raise value
  File "/data/wwwroot/default/gong/jwxt/virtualenv/lib/python3.6/site-packages/flask/app.py", line 2447, in wsgi_app
    response = self.full_dispatch_request()
  File "/data/wwwroot/default/gong/jwxt/virtualenv/lib/python3.6/site-packages/flask/app.py", line 1952, in full_dispatch_request
    rv = self.handle_user_exception(e)
  File "/data/wwwroot/default/gong/jwxt/virtualenv/lib/python3.6/site-packages/flask/app.py", line 1821, in handle_user_exception
    reraise(exc_type, exc_value, tb)
  File "/data/wwwroot/default/gong/jwxt/virtualenv/lib/python3.6/site-packages/flask/_compat.py", line 39, in reraise
    raise value
  File "/data/wwwroot/default/gong/jwxt/virtualenv/lib/python3.6/site-packages/flask/app.py", line 1950, in full_dispatch_request
    rv = self.dispatch_request()
  File "/data/wwwroot/default/gong/jwxt/virtualenv/lib/python3.6/site-packages/flask/app.py", line 1936, in dispatch_request
    return self.view_functions[rule.endpoint](**req.view_args)
  File "/data/wwwroot/default/gong/jwxt/app.py", line 161, in get_now_schedule
    flag = pipiline.get_flag()
  File "/data/wwwroot/default/gong/jwxt/pipeline.py", line 49, in get_flag
    self.cursor.execute(self.check_flag_sql)
  File "/data/wwwroot/default/gong/jwxt/virtualenv/lib/python3.6/site-packages/pymysql/cursors.py", line 163, in execute
    result = self._query(query)
  File "/data/wwwroot/default/gong/jwxt/virtualenv/lib/python3.6/site-packages/pymysql/cursors.py", line 321, in _query
    conn.query(q)
  File "/data/wwwroot/default/gong/jwxt/virtualenv/lib/python3.6/site-packages/pymysql/connections.py", line 504, in query
    self._execute_command(COMMAND.COM_QUERY, sql)
  File "/data/wwwroot/default/gong/jwxt/virtualenv/lib/python3.6/site-packages/pymysql/connections.py", line 742, in _execute_command
    raise err.InterfaceError(0, '')
pymysql.err.InterfaceError: (0, '')
[2020-08-31 00:42:17 +0800] [31756] [ERROR] Error handling request /score/grade
Traceback (most recent call last):
  File "/data/wwwroot/default/gong/jwxt/virtualenv/lib/python3.6/site-packages/gunicorn/workers/base_async.py", line 55, in handle
    self.handle_request(listener_name, req, client, addr)
  File "/data/wwwroot/default/gong/jwxt/virtualenv/lib/python3.6/site-packages/gunicorn/workers/ggevent.py", line 143, in handle_request
    super().handle_request(listener_name, req, sock, addr)
  File "/data/wwwroot/default/gong/jwxt/virtualenv/lib/python3.6/site-packages/gunicorn/workers/base_async.py", line 106, in handle_request
    respiter = self.wsgi(environ, resp.start_response)
  File "/data/wwwroot/default/gong/jwxt/virtualenv/lib/python3.6/site-packages/flask/app.py", line 2464, in __call__
    return self.wsgi_app(environ, start_response)
  File "/data/wwwroot/default/gong/jwxt/virtualenv/lib/python3.6/site-packages/flask/app.py", line 2450, in wsgi_app
    response = self.handle_exception(e)
  File "/data/wwwroot/default/gong/jwxt/virtualenv/lib/python3.6/site-packages/flask/app.py", line 1867, in handle_exception
    reraise(exc_type, exc_value, tb)
  File "/data/wwwroot/default/gong/jwxt/virtualenv/lib/python3.6/site-packages/flask/_compat.py", line 39, in reraise
    raise value
  File "/data/wwwroot/default/gong/jwxt/virtualenv/lib/python3.6/site-packages/flask/app.py", line 2447, in wsgi_app
    response = self.full_dispatch_request()
  File "/data/wwwroot/default/gong/jwxt/virtualenv/lib/python3.6/site-packages/flask/app.py", line 1952, in full_dispatch_request
    rv = self.handle_user_exception(e)
  File "/data/wwwroot/default/gong/jwxt/virtualenv/lib/python3.6/site-packages/flask/app.py", line 1821, in handle_user_exception
    reraise(exc_type, exc_value, tb)
  File "/data/wwwroot/default/gong/jwxt/virtualenv/lib/python3.6/site-packages/flask/_compat.py", line 39, in reraise
    raise value
  File "/data/wwwroot/default/gong/jwxt/virtualenv/lib/python3.6/site-packages/flask/app.py", line 1950, in full_dispatch_request
    rv = self.dispatch_request()
  File "/data/wwwroot/default/gong/jwxt/virtualenv/lib/python3.6/site-packages/flask/app.py", line 1936, in dispatch_request
    return self.view_functions[rule.endpoint](**req.view_args)
  File "/data/wwwroot/default/gong/jwxt/app.py", line 78, in get_grade
    flag = pipiline.get_flag()
  File "/data/wwwroot/default/gong/jwxt/pipeline.py", line 49, in get_flag
    self.cursor.execute(self.check_flag_sql)
  File "/data/wwwroot/default/gong/jwxt/virtualenv/lib/python3.6/site-packages/pymysql/cursors.py", line 163, in execute
    result = self._query(query)
  File "/data/wwwroot/default/gong/jwxt/virtualenv/lib/python3.6/site-packages/pymysql/cursors.py", line 321, in _query
    conn.query(q)
  File "/data/wwwroot/default/gong/jwxt/virtualenv/lib/python3.6/site-packages/pymysql/connections.py", line 505, in query
    self._affected_rows = self._read_query_result(unbuffered=unbuffered)
  File "/data/wwwroot/default/gong/jwxt/virtualenv/lib/python3.6/site-packages/pymysql/connections.py", line 724, in _read_query_result
    result.read()
  File "/data/wwwroot/default/gong/jwxt/virtualenv/lib/python3.6/site-packages/pymysql/connections.py", line 1069, in read
    first_packet = self.connection._read_packet()
  File "/data/wwwroot/default/gong/jwxt/virtualenv/lib/python3.6/site-packages/pymysql/connections.py", line 646, in _read_packet
    packet_header = self._read_bytes(4)
  File "/data/wwwroot/default/gong/jwxt/virtualenv/lib/python3.6/site-packages/pymysql/connections.py", line 699, in _read_bytes
    CR.CR_SERVER_LOST, "Lost connection to MySQL server during query")
pymysql.err.OperationalError: (2013, 'Lost connection to MySQL server during query')
[2020-08-31 00:43:08 +0800] [31756] [ERROR] Error handling request /score/grade
Traceback (most recent call last):
  File "/data/wwwroot/default/gong/jwxt/virtualenv/lib/python3.6/site-packages/gunicorn/workers/base_async.py", line 55, in handle
    self.handle_request(listener_name, req, client, addr)
  File "/data/wwwroot/default/gong/jwxt/virtualenv/lib/python3.6/site-packages/gunicorn/workers/ggevent.py", line 143, in handle_request
    super().handle_request(listener_name, req, sock, addr)
  File "/data/wwwroot/default/gong/jwxt/virtualenv/lib/python3.6/site-packages/gunicorn/workers/base_async.py", line 106, in handle_request
    respiter = self.wsgi(environ, resp.start_response)
  File "/data/wwwroot/default/gong/jwxt/virtualenv/lib/python3.6/site-packages/flask/app.py", line 2464, in __call__
    return self.wsgi_app(environ, start_response)
  File "/data/wwwroot/default/gong/jwxt/virtualenv/lib/python3.6/site-packages/flask/app.py", line 2450, in wsgi_app
    response = self.handle_exception(e)
  File "/data/wwwroot/default/gong/jwxt/virtualenv/lib/python3.6/site-packages/flask/app.py", line 1867, in handle_exception
    reraise(exc_type, exc_value, tb)
  File "/data/wwwroot/default/gong/jwxt/virtualenv/lib/python3.6/site-packages/flask/_compat.py", line 39, in reraise
    raise value
  File "/data/wwwroot/default/gong/jwxt/virtualenv/lib/python3.6/site-packages/flask/app.py", line 2447, in wsgi_app
    response = self.full_dispatch_request()
  File "/data/wwwroot/default/gong/jwxt/virtualenv/lib/python3.6/site-packages/flask/app.py", line 1952, in full_dispatch_request
    rv = self.handle_user_exception(e)
  File "/data/wwwroot/default/gong/jwxt/virtualenv/lib/python3.6/site-packages/flask/app.py", line 1821, in handle_user_exception
    reraise(exc_type, exc_value, tb)
  File "/data/wwwroot/default/gong/jwxt/virtualenv/lib/python3.6/site-packages/flask/_compat.py", line 39, in reraise
    raise value
  File "/data/wwwroot/default/gong/jwxt/virtualenv/lib/python3.6/site-packages/flask/app.py", line 1950, in full_dispatch_request
    rv = self.dispatch_request()
  File "/data/wwwroot/default/gong/jwxt/virtualenv/lib/python3.6/site-packages/flask/app.py", line 1936, in dispatch_request
    return self.view_functions[rule.endpoint](**req.view_args)
  File "/data/wwwroot/default/gong/jwxt/app.py", line 78, in get_grade
    flag = pipiline.get_flag()
  File "/data/wwwroot/default/gong/jwxt/pipeline.py", line 49, in get_flag
    self.cursor.execute(self.check_flag_sql)
  File "/data/wwwroot/default/gong/jwxt/virtualenv/lib/python3.6/site-packages/pymysql/cursors.py", line 163, in execute
    result = self._query(query)
  File "/data/wwwroot/default/gong/jwxt/virtualenv/lib/python3.6/site-packages/pymysql/cursors.py", line 321, in _query
    conn.query(q)
  File "/data/wwwroot/default/gong/jwxt/virtualenv/lib/python3.6/site-packages/pymysql/connections.py", line 504, in query
    self._execute_command(COMMAND.COM_QUERY, sql)
  File "/data/wwwroot/default/gong/jwxt/virtualenv/lib/python3.6/site-packages/pymysql/connections.py", line 742, in _execute_command
    raise err.InterfaceError(0, '')
pymysql.err.InterfaceError: (0, '')
[2020-08-31 00:43:16 +0800] [31756] [ERROR] Error handling request /course
Traceback (most recent call last):
  File "/data/wwwroot/default/gong/jwxt/virtualenv/lib/python3.6/site-packages/gunicorn/workers/base_async.py", line 55, in handle
    self.handle_request(listener_name, req, client, addr)
  File "/data/wwwroot/default/gong/jwxt/virtualenv/lib/python3.6/site-packages/gunicorn/workers/ggevent.py", line 143, in handle_request
    super().handle_request(listener_name, req, sock, addr)
  File "/data/wwwroot/default/gong/jwxt/virtualenv/lib/python3.6/site-packages/gunicorn/workers/base_async.py", line 106, in handle_request
    respiter = self.wsgi(environ, resp.start_response)
  File "/data/wwwroot/default/gong/jwxt/virtualenv/lib/python3.6/site-packages/flask/app.py", line 2464, in __call__
    return self.wsgi_app(environ, start_response)
  File "/data/wwwroot/default/gong/jwxt/virtualenv/lib/python3.6/site-packages/flask/app.py", line 2450, in wsgi_app
    response = self.handle_exception(e)
  File "/data/wwwroot/default/gong/jwxt/virtualenv/lib/python3.6/site-packages/flask/app.py", line 1867, in handle_exception
    reraise(exc_type, exc_value, tb)
  File "/data/wwwroot/default/gong/jwxt/virtualenv/lib/python3.6/site-packages/flask/_compat.py", line 39, in reraise
    raise value
  File "/data/wwwroot/default/gong/jwxt/virtualenv/lib/python3.6/site-packages/flask/app.py", line 2447, in wsgi_app
    response = self.full_dispatch_request()
  File "/data/wwwroot/default/gong/jwxt/virtualenv/lib/python3.6/site-packages/flask/app.py", line 1952, in full_dispatch_request
    rv = self.handle_user_exception(e)
  File "/data/wwwroot/default/gong/jwxt/virtualenv/lib/python3.6/site-packages/flask/app.py", line 1821, in handle_user_exception
    reraise(exc_type, exc_value, tb)
  File "/data/wwwroot/default/gong/jwxt/virtualenv/lib/python3.6/site-packages/flask/_compat.py", line 39, in reraise
    raise value
  File "/data/wwwroot/default/gong/jwxt/virtualenv/lib/python3.6/site-packages/flask/app.py", line 1950, in full_dispatch_request
    rv = self.dispatch_request()
  File "/data/wwwroot/default/gong/jwxt/virtualenv/lib/python3.6/site-packages/flask/app.py", line 1936, in dispatch_request
    return self.view_functions[rule.endpoint](**req.view_args)
  File "/data/wwwroot/default/gong/jwxt/app.py", line 161, in get_now_schedule
    flag = pipiline.get_flag()
  File "/data/wwwroot/default/gong/jwxt/pipeline.py", line 49, in get_flag
    self.cursor.execute(self.check_flag_sql)
  File "/data/wwwroot/default/gong/jwxt/virtualenv/lib/python3.6/site-packages/pymysql/cursors.py", line 163, in execute
    result = self._query(query)
  File "/data/wwwroot/default/gong/jwxt/virtualenv/lib/python3.6/site-packages/pymysql/cursors.py", line 321, in _query
    conn.query(q)
  File "/data/wwwroot/default/gong/jwxt/virtualenv/lib/python3.6/site-packages/pymysql/connections.py", line 504, in query
    self._execute_command(COMMAND.COM_QUERY, sql)
  File "/data/wwwroot/default/gong/jwxt/virtualenv/lib/python3.6/site-packages/pymysql/connections.py", line 742, in _execute_command
    raise err.InterfaceError(0, '')
pymysql.err.InterfaceError: (0, '')
[2020-08-31 00:43:27 +0800] [31756] [ERROR] Error handling request /score/grade
Traceback (most recent call last):
  File "/data/wwwroot/default/gong/jwxt/virtualenv/lib/python3.6/site-packages/gunicorn/workers/base_async.py", line 55, in handle
    self.handle_request(listener_name, req, client, addr)
  File "/data/wwwroot/default/gong/jwxt/virtualenv/lib/python3.6/site-packages/gunicorn/workers/ggevent.py", line 143, in handle_request
    super().handle_request(listener_name, req, sock, addr)
  File "/data/wwwroot/default/gong/jwxt/virtualenv/lib/python3.6/site-packages/gunicorn/workers/base_async.py", line 106, in handle_request
    respiter = self.wsgi(environ, resp.start_response)
  File "/data/wwwroot/default/gong/jwxt/virtualenv/lib/python3.6/site-packages/flask/app.py", line 2464, in __call__
    return self.wsgi_app(environ, start_response)
  File "/data/wwwroot/default/gong/jwxt/virtualenv/lib/python3.6/site-packages/flask/app.py", line 2450, in wsgi_app
    response = self.handle_exception(e)
  File "/data/wwwroot/default/gong/jwxt/virtualenv/lib/python3.6/site-packages/flask/app.py", line 1867, in handle_exception
    reraise(exc_type, exc_value, tb)
  File "/data/wwwroot/default/gong/jwxt/virtualenv/lib/python3.6/site-packages/flask/_compat.py", line 39, in reraise
    raise value
  File "/data/wwwroot/default/gong/jwxt/virtualenv/lib/python3.6/site-packages/flask/app.py", line 2447, in wsgi_app
    response = self.full_dispatch_request()
  File "/data/wwwroot/default/gong/jwxt/virtualenv/lib/python3.6/site-packages/flask/app.py", line 1952, in full_dispatch_request
    rv = self.handle_user_exception(e)
  File "/data/wwwroot/default/gong/jwxt/virtualenv/lib/python3.6/site-packages/flask/app.py", line 1821, in handle_user_exception
    reraise(exc_type, exc_value, tb)
  File "/data/wwwroot/default/gong/jwxt/virtualenv/lib/python3.6/site-packages/flask/_compat.py", line 39, in reraise
    raise value
  File "/data/wwwroot/default/gong/jwxt/virtualenv/lib/python3.6/site-packages/flask/app.py", line 1950, in full_dispatch_request
    rv = self.dispatch_request()
  File "/data/wwwroot/default/gong/jwxt/virtualenv/lib/python3.6/site-packages/flask/app.py", line 1936, in dispatch_request
    return self.view_functions[rule.endpoint](**req.view_args)
  File "/data/wwwroot/default/gong/jwxt/app.py", line 78, in get_grade
    flag = pipiline.get_flag()
  File "/data/wwwroot/default/gong/jwxt/pipeline.py", line 49, in get_flag
    self.cursor.execute(self.check_flag_sql)
  File "/data/wwwroot/default/gong/jwxt/virtualenv/lib/python3.6/site-packages/pymysql/cursors.py", line 163, in execute
    result = self._query(query)
  File "/data/wwwroot/default/gong/jwxt/virtualenv/lib/python3.6/site-packages/pymysql/cursors.py", line 321, in _query
    conn.query(q)
  File "/data/wwwroot/default/gong/jwxt/virtualenv/lib/python3.6/site-packages/pymysql/connections.py", line 504, in query
    self._execute_command(COMMAND.COM_QUERY, sql)
  File "/data/wwwroot/default/gong/jwxt/virtualenv/lib/python3.6/site-packages/pymysql/connections.py", line 742, in _execute_command
    raise err.InterfaceError(0, '')
pymysql.err.InterfaceError: (0, '')
[2020-08-31 00:51:07 +0800] [22748] [ERROR] Error handling request /associated_schedule
Traceback (most recent call last):
  File "/data/wwwroot/default/gong/jwxt/virtualenv/lib/python3.6/site-packages/gunicorn/workers/base_async.py", line 55, in handle
    self.handle_request(listener_name, req, client, addr)
  File "/data/wwwroot/default/gong/jwxt/virtualenv/lib/python3.6/site-packages/gunicorn/workers/ggevent.py", line 143, in handle_request
    super().handle_request(listener_name, req, sock, addr)
  File "/data/wwwroot/default/gong/jwxt/virtualenv/lib/python3.6/site-packages/gunicorn/workers/base_async.py", line 106, in handle_request
    respiter = self.wsgi(environ, resp.start_response)
  File "/data/wwwroot/default/gong/jwxt/virtualenv/lib/python3.6/site-packages/flask/app.py", line 2464, in __call__
    return self.wsgi_app(environ, start_response)
  File "/data/wwwroot/default/gong/jwxt/virtualenv/lib/python3.6/site-packages/flask/app.py", line 2450, in wsgi_app
    response = self.handle_exception(e)
  File "/data/wwwroot/default/gong/jwxt/virtualenv/lib/python3.6/site-packages/flask/app.py", line 1867, in handle_exception
    reraise(exc_type, exc_value, tb)
  File "/data/wwwroot/default/gong/jwxt/virtualenv/lib/python3.6/site-packages/flask/_compat.py", line 39, in reraise
    raise value
  File "/data/wwwroot/default/gong/jwxt/virtualenv/lib/python3.6/site-packages/flask/app.py", line 2447, in wsgi_app
    response = self.full_dispatch_request()
  File "/data/wwwroot/default/gong/jwxt/virtualenv/lib/python3.6/site-packages/flask/app.py", line 1952, in full_dispatch_request
    rv = self.handle_user_exception(e)
  File "/data/wwwroot/default/gong/jwxt/virtualenv/lib/python3.6/site-packages/flask/app.py", line 1821, in handle_user_exception
    reraise(exc_type, exc_value, tb)
  File "/data/wwwroot/default/gong/jwxt/virtualenv/lib/python3.6/site-packages/flask/_compat.py", line 39, in reraise
    raise value
  File "/data/wwwroot/default/gong/jwxt/virtualenv/lib/python3.6/site-packages/flask/app.py", line 1950, in full_dispatch_request
    rv = self.dispatch_request()
  File "/data/wwwroot/default/gong/jwxt/virtualenv/lib/python3.6/site-packages/flask/app.py", line 1936, in dispatch_request
    return self.view_functions[rule.endpoint](**req.view_args)
  File "/data/wwwroot/default/gong/jwxt/app.py", line 257, in get_associated_schedule
    name = infopipeline.output_data()['name']
  File "/data/wwwroot/default/gong/jwxt/pipeline.py", line 360, in output_data
    result = results[0]
IndexError: list index out of range
[2020-08-31 10:43:51 +0800] [22748] [ERROR] Error handling request /score/grade
Traceback (most recent call last):
  File "/data/wwwroot/default/gong/jwxt/virtualenv/lib/python3.6/site-packages/gunicorn/workers/base_async.py", line 55, in handle
    self.handle_request(listener_name, req, client, addr)
  File "/data/wwwroot/default/gong/jwxt/virtualenv/lib/python3.6/site-packages/gunicorn/workers/ggevent.py", line 143, in handle_request
    super().handle_request(listener_name, req, sock, addr)
  File "/data/wwwroot/default/gong/jwxt/virtualenv/lib/python3.6/site-packages/gunicorn/workers/base_async.py", line 106, in handle_request
    respiter = self.wsgi(environ, resp.start_response)
  File "/data/wwwroot/default/gong/jwxt/virtualenv/lib/python3.6/site-packages/flask/app.py", line 2464, in __call__
    return self.wsgi_app(environ, start_response)
  File "/data/wwwroot/default/gong/jwxt/virtualenv/lib/python3.6/site-packages/flask/app.py", line 2450, in wsgi_app
    response = self.handle_exception(e)
  File "/data/wwwroot/default/gong/jwxt/virtualenv/lib/python3.6/site-packages/flask/app.py", line 1867, in handle_exception
    reraise(exc_type, exc_value, tb)
  File "/data/wwwroot/default/gong/jwxt/virtualenv/lib/python3.6/site-packages/flask/_compat.py", line 39, in reraise
    raise value
  File "/data/wwwroot/default/gong/jwxt/virtualenv/lib/python3.6/site-packages/flask/app.py", line 2447, in wsgi_app
    response = self.full_dispatch_request()
  File "/data/wwwroot/default/gong/jwxt/virtualenv/lib/python3.6/site-packages/flask/app.py", line 1952, in full_dispatch_request
    rv = self.handle_user_exception(e)
  File "/data/wwwroot/default/gong/jwxt/virtualenv/lib/python3.6/site-packages/flask/app.py", line 1821, in handle_user_exception
    reraise(exc_type, exc_value, tb)
  File "/data/wwwroot/default/gong/jwxt/virtualenv/lib/python3.6/site-packages/flask/_compat.py", line 39, in reraise
    raise value
  File "/data/wwwroot/default/gong/jwxt/virtualenv/lib/python3.6/site-packages/flask/app.py", line 1950, in full_dispatch_request
    rv = self.dispatch_request()
  File "/data/wwwroot/default/gong/jwxt/virtualenv/lib/python3.6/site-packages/flask/app.py", line 1936, in dispatch_request
    return self.view_functions[rule.endpoint](**req.view_args)
  File "/data/wwwroot/default/gong/jwxt/app.py", line 78, in get_grade
    flag = pipiline.get_flag()
  File "/data/wwwroot/default/gong/jwxt/pipeline.py", line 49, in get_flag
    self.cursor.execute(self.check_flag_sql)
  File "/data/wwwroot/default/gong/jwxt/virtualenv/lib/python3.6/site-packages/pymysql/cursors.py", line 163, in execute
    result = self._query(query)
  File "/data/wwwroot/default/gong/jwxt/virtualenv/lib/python3.6/site-packages/pymysql/cursors.py", line 321, in _query
    conn.query(q)
  File "/data/wwwroot/default/gong/jwxt/virtualenv/lib/python3.6/site-packages/pymysql/connections.py", line 505, in query
    self._affected_rows = self._read_query_result(unbuffered=unbuffered)
  File "/data/wwwroot/default/gong/jwxt/virtualenv/lib/python3.6/site-packages/pymysql/connections.py", line 724, in _read_query_result
    result.read()
  File "/data/wwwroot/default/gong/jwxt/virtualenv/lib/python3.6/site-packages/pymysql/connections.py", line 1069, in read
    first_packet = self.connection._read_packet()
  File "/data/wwwroot/default/gong/jwxt/virtualenv/lib/python3.6/site-packages/pymysql/connections.py", line 646, in _read_packet
    packet_header = self._read_bytes(4)
  File "/data/wwwroot/default/gong/jwxt/virtualenv/lib/python3.6/site-packages/pymysql/connections.py", line 699, in _read_bytes
    CR.CR_SERVER_LOST, "Lost connection to MySQL server during query")
pymysql.err.OperationalError: (2013, 'Lost connection to MySQL server during query')
[2020-08-31 11:05:13 +0800] [3324] [ERROR] Exception in worker process
Traceback (most recent call last):
  File "/data/wwwroot/default/gong/jwxt/virtualenv/lib/python3.6/site-packages/gunicorn/arbiter.py", line 583, in spawn_worker
    worker.init_process()
  File "/data/wwwroot/default/gong/jwxt/virtualenv/lib/python3.6/site-packages/gunicorn/workers/ggevent.py", line 162, in init_process
    super().init_process()
  File "/data/wwwroot/default/gong/jwxt/virtualenv/lib/python3.6/site-packages/gunicorn/workers/base.py", line 119, in init_process
    self.load_wsgi()
  File "/data/wwwroot/default/gong/jwxt/virtualenv/lib/python3.6/site-packages/gunicorn/workers/base.py", line 144, in load_wsgi
    self.wsgi = self.app.wsgi()
  File "/data/wwwroot/default/gong/jwxt/virtualenv/lib/python3.6/site-packages/gunicorn/app/base.py", line 67, in wsgi
    self.callable = self.load()
  File "/data/wwwroot/default/gong/jwxt/virtualenv/lib/python3.6/site-packages/gunicorn/app/wsgiapp.py", line 49, in load
    return self.load_wsgiapp()
  File "/data/wwwroot/default/gong/jwxt/virtualenv/lib/python3.6/site-packages/gunicorn/app/wsgiapp.py", line 39, in load_wsgiapp
    return util.import_app(self.app_uri)
  File "/data/wwwroot/default/gong/jwxt/virtualenv/lib/python3.6/site-packages/gunicorn/util.py", line 358, in import_app
    mod = importlib.import_module(module)
  File "/usr/lib64/python3.6/importlib/__init__.py", line 126, in import_module
    return _bootstrap._gcd_import(name[level:], package, level)
  File "<frozen importlib._bootstrap>", line 994, in _gcd_import
  File "<frozen importlib._bootstrap>", line 971, in _find_and_load
  File "<frozen importlib._bootstrap>", line 955, in _find_and_load_unlocked
  File "<frozen importlib._bootstrap>", line 665, in _load_unlocked
  File "<frozen importlib._bootstrap_external>", line 678, in exec_module
  File "<frozen importlib._bootstrap>", line 219, in _call_with_frames_removed
  File "/data/wwwroot/default/gong/jwxt/app.py", line 6, in <module>
    from pipeline import InfoPipeline, GradePipeline, SchedulePipeline, ExamPipeline, GPAPipeline
  File "/data/wwwroot/default/gong/jwxt/pipeline.py", line 14
    self.cursor = self.connection.cursor()
                                         ^
TabError: inconsistent use of tabs and spaces in indentation
